'solc --version' running
'solc Reentrancy.sol --combined-json abi,ast,bin,bin-runtime,srcmap,srcmap-runtime,userdoc,devdoc,hashes --allow-paths .,/Users/austinli/College/COS-ECE-473-Course-24/COS473FinalProject' running
Compilation warnings/errors on Reentrancy.sol:
Error: Undeclared identifier.
  --> Reentrancy.sol:22:17:
   |
22 |         require(success, "Failed to send Ether");
   |                 ^^^^^^^


Traceback (most recent call last):
  File "/opt/homebrew/lib/python3.11/site-packages/crytic_compile/platform/solc.py", line 582, in _run_solc
    ret: Dict = json.loads(stdout)
                ^^^^^^^^^^^^^^^^^^
  File "/opt/homebrew/Cellar/python@3.11/3.11.6_1/Frameworks/Python.framework/Versions/3.11/lib/python3.11/json/__init__.py", line 346, in loads
    return _default_decoder.decode(s)
           ^^^^^^^^^^^^^^^^^^^^^^^^^^
  File "/opt/homebrew/Cellar/python@3.11/3.11.6_1/Frameworks/Python.framework/Versions/3.11/lib/python3.11/json/decoder.py", line 337, in decode
    obj, end = self.raw_decode(s, idx=_w(s, 0).end())
               ^^^^^^^^^^^^^^^^^^^^^^^^^^^^^^^^^^^^^^
  File "/opt/homebrew/Cellar/python@3.11/3.11.6_1/Frameworks/Python.framework/Versions/3.11/lib/python3.11/json/decoder.py", line 355, in raw_decode
    raise JSONDecodeError("Expecting value", s, err.value) from None
json.decoder.JSONDecodeError: Expecting value: line 1 column 1 (char 0)

During handling of the above exception, another exception occurred:

Traceback (most recent call last):
  File "/opt/homebrew/bin/slither", line 8, in <module>
    sys.exit(main())
             ^^^^^^
  File "/opt/homebrew/lib/python3.11/site-packages/slither/__main__.py", line 746, in main
    main_impl(all_detector_classes=detectors, all_printer_classes=printers)
  File "/opt/homebrew/lib/python3.11/site-packages/slither/__main__.py", line 852, in main_impl
    ) = process_all(filename, args, detector_classes, printer_classes)
        ^^^^^^^^^^^^^^^^^^^^^^^^^^^^^^^^^^^^^^^^^^^^^^^^^^^^^^^^^^^^^^
  File "/opt/homebrew/lib/python3.11/site-packages/slither/__main__.py", line 96, in process_all
    compilations = compile_all(target, **vars(args))
                   ^^^^^^^^^^^^^^^^^^^^^^^^^^^^^^^^^
  File "/opt/homebrew/lib/python3.11/site-packages/crytic_compile/crytic_compile.py", line 718, in compile_all
    compilations.append(CryticCompile(target, **kwargs))
                        ^^^^^^^^^^^^^^^^^^^^^^^^^^^^^^^
  File "/opt/homebrew/lib/python3.11/site-packages/crytic_compile/crytic_compile.py", line 207, in __init__
    self._compile(**kwargs)
  File "/opt/homebrew/lib/python3.11/site-packages/crytic_compile/crytic_compile.py", line 629, in _compile
    self._platform.compile(self, **kwargs)
  File "/opt/homebrew/lib/python3.11/site-packages/crytic_compile/platform/solc.py", line 151, in compile
    targets_json = _get_targets_json(compilation_unit, self._target, **kwargs)
                   ^^^^^^^^^^^^^^^^^^^^^^^^^^^^^^^^^^^^^^^^^^^^^^^^^^^^^^^^^^^
  File "/opt/homebrew/lib/python3.11/site-packages/crytic_compile/platform/solc.py", line 280, in _get_targets_json
    return _run_solc(
           ^^^^^^^^^^
  File "/opt/homebrew/lib/python3.11/site-packages/crytic_compile/platform/solc.py", line 586, in _run_solc
    raise InvalidCompilation(f"Invalid solc compilation {stderr}")
crytic_compile.platform.exceptions.InvalidCompilation: Invalid solc compilation Error: Undeclared identifier.
  --> Reentrancy.sol:22:17:
   |
22 |         require(success, "Failed to send Ether");
   |                 ^^^^^^^


